Workbook
Name _ftn1: 'CIS CSAT Pro'!$G$20
Name _ftnref1: 'CIS CSAT Pro'!$G$8
Name _Hlk82606169: 'CIS CSAT Pro'!$G$14
Name AcceptableRisk: '2. Enterprise Parameters'!$E$35
Name AcceptableRisk1: 'Enterprise Parameters -EXAMPLE'!$E$35
Name Asset_Class: tblVCDBIndex[[#All],[Asset Class]]
Name Maturity_Score: tblMaturityScores[Maturity Scores]

Sheet Cover

Sheet Read_Me
A1: CIS RAM v2.2 for IG2
A2: The CIS RAM for IG2 Workbook protects most cells in the Risk Register and lookup tables to prevent users from accidentally changing the formulas and lookups that automate the risk analysis and make it simple. If users are confident in their use of Microsoft® Excel and wish to modify values, such as Risk Acceptance Criteria, they may “unprotect” the document by going to the “Review” tab in the Excel menu and selecting the “Unprotect sheet” button. However, guidance for maintenance of the Workbook, formulas, lookups, and protected cells is beyond the scope of this document.

Sheet Important Resources
D5: Remember to download the CIS Controls Version 8.1 Guide where you can learn more about: - This Version of the CIS Controls - The CIS Controls Ecosystem ("It's not about the list') - How to Get Started - Using or Transitioning from Prior Versions of the CIS Controls - Structure of the CIS Controls - Implementation Groups - Why is this Control critical - Procedures and tools
D6: https://www.cisecurity.org/controls/v8-1/
D7: https://www.cisecurity.org/controls/resources?crc=about-the-cis-critical-security-controls
D10: A free tool with a dynamic list of the CIS Safeguards that can be filtered by Implemtation Groups and mappings to multiple frameworks.
D11: https://www.cisecurity.org/controls/cis-controls-navigator
D16: Join our community where you can discuss the CIS Controls with our global army of experts and voluneers!
D17: https://workbench.cisecurity.org/dashboard
D19: CIS CSAT (Controls Self Assessment Tool)
D21: Overview: The CIS Controls® Self Assessment Tool, also known as CIS CSAT, enables organizations to assess and track their implementation of the CIS Controls for Versions 8 and 7.1. The CIS Controls are a prioritized set of consensus-developed security best practices used by organizations around the world to defend against cyber threats.
D23: TWO TYPES:
D25: CIS-Hosted CSAT: The CIS-hosted version of CIS CSAT is free to every organization for use in a non-commercial capacity to conduct CIS Controls assessments of their organization. (released January 2019)
D26: https://csat.cisecurity.org/
... D29: https://www.cisecurity.org/controls/cis-controls-self-assessment-tool-cis-csat/

Sheet 1. Impact Criteria Survey 
D2: Prompt | E2: Response
B3: 1 | C3: Mission | D3: How would you concisely describe the benefit that your enterprise provides your customers, clients, constituents, or the public? This is why they engage in this risk with you.
C5: Instructions: Imagine that your enterprise suffers a cybersecurity or information security incident. Describe in the spaces provided below how you would determine that the impacts to your mission were acceptable, or unacceptable.
C7: Impact Magnitude | D7: Prompt | E7: Response
C8: Negligible | D8: What observable evidence would you have that your mission - as you defined it above - would be unaffected? | E8: The mission would remain intact.
C9: Acceptable | D9: What observable evidence would you have that your mission would be compromised, but it would not require correction? | E9: This mission would not be perfectly achieved, but could be recovered within normal operations.
C10: Unacceptable | D10: What observable evidence would you have that your mission would be compromised in a way that would require correction, but the correction could be achieved through the normal course of business? | E10: This mission would not be achieved, and would require short-term, unplanned efforts, resources, or investments to recover.
C11: High | D11: What observable evidence would you have that your mission would be compromised so badly that extraordinary efforts would be required to restore it? | E11: This mission would not be achieved. If significant, unplanned efforts, resources, or investments are not made, the mission may not ever be achievable.
C12: Catastrophic | D12: What observable evidence would you have that your mission would be compromised so badly that it could not be achieved? | E12: The mission would not be achievable.
D15: Prompt | E15: Response
B16: 2 | C16: Operational Objectives | D16: What business or organizational goals does the enterprise attempt to achieve?
C18: Instructions: Imagine that your enterprise suffers a cybersecurity or information security incident. Describe in the spaces provided below how you would determine that the impacts to your operational objectives were acceptable, or unacceptable.
C20: Impact Magnitude | D20: Prompt | E20: Response
C21: Negligible | D21: What observable evidence would you have that your operational objectives - as you defined them above - would be unaffected? | E21: Growth plan would be intact.
C22: Acceptable | D22: What observable evidence would you have that your operational objectives would be compromised, but it would not require correction? | E22: Growth plan would be off target, but within variance.
C23: Unacceptable | D23: What observable evidence would you have that your operational objectives would be compromised in a way that would require correction, but the correction could be achieved through the normal course of business? | E23: Growth plan would be out of variance, but can be recovered within a fiscal year.
C24: High | D24: What observable evidence would you have that your operational objectives would be compromised so badly that extraordinary efforts would be required to restore them? | E24: Growth plan would be out of variance, and may require multiple years to correct.
C25: Catastrophic | D25: What observable evidence would you have that your operational objectives would be compromised so badly that they could not be achieved? | E25: We would not be able to grow.
D28: Prompt | E28: Response
B29: 3 | C29: Financial Objectives | D29: What are the unexpected cost outlays that your enterprise could or could not tolerate?
C31: Instructions: Imagine that your enterprise suffers a cybersecurity or information security incident. Describe in the spaces provided below how you would determine that the impacts to your financial objectives were acceptable, or unacceptable.
C33: Impact Magnitude | D33: Prompt | E33: Response
C34: Negligible | D34: What observable evidence would you have that your financial objectives - as you defined them above - would be unaffected?
C35: Acceptable | D35: What observable evidence would you have that your financial objectives would be compromised, but it would not require correction?
C36: Unacceptable | D36: What observable evidence would you have that your financial objectives would be compromised in a way that would require correction, but the correction could be achieved through the normal course of business?
C37: High | D37: What observable evidence would you have that your financial objectives would be compromised so badly that extraordinary efforts would be required to restore them?
C38: Catastrophic | D38: Leave this blank
D41: Prompt | E41: Response
B42: 4 | C42: Obligations | D42: What harm may foreseeably come to others as a result of a cybersecurity incident?
C44: Instructions: Imagine that your enterprise suffers a cybersecurity or information security incident. Describe in the spaces provided below how you would determine that the impacts to your obligations (harm, to others) were acceptable, or unacceptable.
C46: Impact Magnitude | D46: Prompt | E46: Response
C47: Negligible | D47: Describe a condition where others would not be harmed. | E47: No harm could foreseeably result.
C48: Acceptable | D48: Describe a condition where others would not be harmed to a degree that required correction or compensation. | E48: Any harm that could result would not require correction, repair, or compensation to make the harmed parties "whole."
C49: Unacceptable | D49: Describe a condition where one or few others would be harmed to a degree that you could correct. | E49: Correctible harm may occur to one or few others.
C50: High | D50: Describe a condition where many others would be harmed to a degree that you could correct, or where few others are harmed to a degree that others would always have a small degree of impairment. | E50: Correctible harm may occur to many others, or harm that can be partially corrected for a few others may occur.
C51: Catastrophic | D51: Describe a condition where others would be irreparably harmed. | E51: We would not be able to protect others from any degree of harm.

Sheet 2. Enterprise Parameters
B2: 1 | C2: Enterprise Risk Assessment Criteria | D2: Enterprise Name
D3: Scope
D4: Last Completed (Date)
B8: 2 | C8: Impact Criteria
C10: Impact Scores | D10: Mission | E10: Operational Objectives | F10: Financial Objectives | G10: Obligations
C11: Definition | F11: =IF(ISBLANK('1. Impact Criteria Survey '!E29),"",'1. Impact Criteria Survey '!E29)
C12: 1. Negligible | D12: The mission would remain intact. | E12: Growth plan would be intact. | F12: =IF(ISBLANK('1. Impact Criteria Survey '!E34),"",'1. Impact Criteria Survey '!E34) | G12: No harm could foreseeably result.
C13: 2. Acceptable | D13: This mission would not be perfectly achieved, but could be recovered within normal operations. | E13: Growth plan would be off target, but within variance. | F13: =IF(ISBLANK('1. Impact Criteria Survey '!E35),"",'1. Impact Criteria Survey '!E35) | G13: Any harm that could result would not require correction, repair, or compensation to make the harmed parties "whole."
C14: 3. Unacceptable | D14: This mission would not be achieved, and would require short-term, unplanned efforts, resources, or investments to recover. | E14: Growth plan would be out of variance, but can be recovered within a fiscal year. | F14: =IF(ISBLANK('1. Impact Criteria Survey '!E36),"",'1. Impact Criteria Survey '!E36) | G14: Correctible harm may occur to one or few others.
C15: 4. High | D15: This mission would not be achieved. If significant, unplanned efforts, resources, or investments are not made, the mission may not ever be achievable. | E15: Growth plan would be out of variance, and may require multiple years to correct. | F15: =IF(ISBLANK('1. Impact Criteria Survey '!E37),"",'1. Impact Criteria Survey '!E37) | G15: Correctible harm may occur to many others, or harm that can be partially corrected for a few others may occur.
C16: 5. Catastrophic | D16: The mission would not be achievable. | E16: We would not be able to grow. | F16: =IF(ISBLANK('1. Impact Criteria Survey '!E38),"",'1. Impact Criteria Survey '!E38) | G16: We would not be able to protect others from any degree of harm.
B20: 3 | C20: Expectancy Criteria
C22: Expectancy Score | D22: Expectancy | E22: Criteria
C23: 1 | D23: Remote | E23: Safeguard would reliably prevent the threat.
C24: 2 | D24: Unlikely | E24: Safeguard would reliably prevent most occurrences of the threat.
C25: 3 | D25: As likely as not | E25: Safeguard would prevent as many threat occurrences as it would miss.
C26: 4 | D26: Likely | E26: Safeguard would prevent few threat occurrences.
C27: 5 | D27: Certain | E27: Safeguard would not prevent threat occurrences.
B31: 4 | C31: Risk Acceptance Criteria
C33: We would start to invest against risks to prevent this expectancy and impact, or higher. | D33: Expectancy | E33: Impact
D35: Acceptable Risk is less than … | E35: =D34*E34 -> 0
B39: 5 | C39: Inherent Risk Criteria | D39: What is the highest impact to the Mission, Operational Objectives, Financial Objectives, and Obligations that each Asset Type could cause?
C41: Asset Class | D41: Mission Impact | E41: Operational Objectives Impact | F41: Financial Objectives Impact | G41: Obligations Impact
C42: Software
C43: Data
C44: Devices
C45: Network
C46: Users
C47: Documentation

Sheet 3. Risk Register Controls v8.1
B2: Enterprise Risk Assessment Criteria | C2: Enterprise Name | D2: =IF(ISBLANK('2. Enterprise Parameters'!E2),"",'2. Enterprise Parameters'!E2)
C3: Scope | D3: =IF(ISBLANK('2. Enterprise Parameters'!E3),"",'2. Enterprise Parameters'!E3)
C4: Last Completed (Date) | D4: =IF(ISBLANK('2. Enterprise Parameters'!E4),"",'2. Enterprise Parameters'!E4)
B8: Risk Register | C8: Risk Analysis | U8: Risk Register | V8: Risk Treatment | AL8: Reasonable Annual Cost
B10: Asset Class | C10: Asset Name | D10: CIS Safeguard | E10: CIS Safeguard Title | F10: IG1 | G10: IG2 | H10: NIST CSF Security Function | I10: Our Implementation | J10: Evidence of Implementation | K10: Vulnerabilities | L10: Safeguard Maturity Score | M10: VCDB Index | N10: Expectancy Score | O10: Impact to Mission | P10: Impact to Operational Objectives | Q10: Impact to Financial Objectives | R10: Impact to Obligations | S10: Risk Score | T10: Risk Level | U10: Risk Treatment Option | V10: Risk Treatment Safeguard | W10: Risk Treatment Safeguard Title | X10: Risk Treatment Safeguard Description | Y10: Our Planned Implementation | Z10: Risk Treatment Safeguard Maturity Score | AA10: Risk Treatment Safeguard Expectancy Score | AB10: Risk Treatment Safeguard Impact to Mission | AC10: Risk Treatment Safeguard Impact to Operational Objectives | AD10: Risk Treatment Safeguard Impact to Financial Objectives | AE10: Risk Treatment Safeguard Impact to Obligations | AF10: Risk Treatment Safeguard Risk Score | AG10: Reasonable and Acceptable | AH10: Risk Treatment Safeguard Cost | AI10: Implementation Quarter | AJ10: Implementation Year | AL10: Impact to Financial Objectives | AM10: Year | AN10: Reasonable?
B11: Devices | D11: 1.1 | E11: Establish and Maintain Detailed Enterprise Asset Inventory | F11: x | G11: x | H11: Identify | M11: =IFERROR(VLOOKUP(tblRiskRegister32[[#This Row],[Asset Class]],tblVCDBIndex[],4,FALSE),"") -> 4 | N11: =IFERROR(VLOOKUP(10*tblRiskRegister32[[#This Row],[Safeguard Maturity Score]]+tblRiskRegister32[[#This Row],[VCDB Index]],tblHITIndexWeightTable[],4,FALSE),"") | O11: =VLOOKUP(tblRiskRegister32[[#This Row],[Asset Class]],tblInherentImpacts30[],2,FALSE) -> 0 | P11: =VLOOKUP(tblRiskRegister32[[#This Row],[Asset Class]],tblInherentImpacts30[],3,FALSE) -> 0 | Q11: =VLOOKUP(tblRiskRegister32[[#This Row],[Asset Class]],tblInherentImpacts30[],4,FALSE) -> 0 | R11: =VLOOKUP(tblRiskRegister32[[#This Row],[Asset Class]],tblInherentImpacts30[],5,FALSE) -> 0 | S11: =IFERROR(MAX(tblRiskRegister32[[#This Row],[Impact to Mission]:[Impact to Obligations]])*tblRiskRegister32[[#This Row],[Expectancy Score]],"") | T11: =tblRiskRegister32[[#This Row],[Risk Score]] | V11: 1.1 | W11: Establish and Maintain Detailed Enterprise Asset Inventory | X11: Establish and maintain an accurate, detailed, and up-to-date inventory of all enterprise assets with the potential to store or process data, to include: end-user devices (including portable and mobile), network devices, non-computing/IoT devices, and servers. Ensure the inventory records the network address (if static), hardware address, machine name, enterprise asset owner, department for each asset, and whether the asset has been approved to connect to the network. For mobile end-user devices, MDM type tools can support this process, where appropriate. This inventory includes assets connected to the infrastructure physically, virtually, remotely, and those within cloud environments. Additionally, it includes assets that are regularly connected to the enterprise’s network infrastructure, even if they are not under control of the enterprise. Review and update the inventory of all enterprise assets bi-annually, or more frequently. | AA11: =IFERROR(VLOOKUP(10*tblRiskRegister32[[#This Row],[Risk Treatment Safeguard Maturity Score]]+tblRiskRegister32[[#This Row],[VCDB Index]],tblHITIndexWeightTable[],4,FALSE),"") | AB11: =VLOOKUP(tblRiskRegister32[[#This Row],[Asset Class]],tblInherentImpacts30[],2,FALSE) -> 0 | AC11: =VLOOKUP(tblRiskRegister32[[#This Row],[Asset Class]],tblInherentImpacts30[],3,FALSE) -> 0 | AD11: =VLOOKUP(tblRiskRegister32[[#This Row],[Asset Class]],tblInherentImpacts30[],4,FALSE) -> 0 | AE11: =VLOOKUP(tblRiskRegister32[[#This Row],[Asset Class]],tblInherentImpacts30[],5,FALSE) -> 0 | AF11: =IFERROR(MAX(tblRiskRegister32[[#This Row],[Risk Treatment Safeguard Impact to Mission]:[Risk Treatment Safeguard Impact to Obligations]])*tblRiskRegister32[[#This Row],[Risk Treatment Safeguard Expectancy Score]],"") | AG11: =IF(tblRiskRegister32[[#This Row],[Risk Score]]>=AcceptableRisk,IF(tblRiskRegister32[[#This Row],[Risk Treatment Safeguard Risk Score]]<AcceptableRisk, IF(tblRiskRegister32[[#This Row],[Risk Treatment Safeguard Risk Score]]<tblRiskRegister32[[#This Row],[Risk Score]],"Yes","No"),"No"),"Yes") -> No | AL11: =SUMIF(tblRiskRegister32[[#All],[Implementation Year]],"="&tblCostImpacts33[[#This Row],[Year]],tblRiskRegister32[[#All],[Risk Treatment Safeguard Cost]]) -> 0 | AM11: 2025 | AN11: =IF(tblCostImpacts33[[#This Row],[Impact to Financial Objectives]]<='2. Enterprise Parameters'!$F$13,"Yes","No") -> Yes
B12: Devices | D12: 1.2 | E12: Address Unauthorized Assets | F12: x | G12: x | H12: Respond | M12: =IFERROR(VLOOKUP(tblRiskRegister32[[#This Row],[Asset Class]],tblVCDBIndex[],4,FALSE),"") -> 4 | N12: =IFERROR(VLOOKUP(10*tblRiskRegister32[[#This Row],[Safeguard Maturity Score]]+tblRiskRegister32[[#This Row],[VCDB Index]],tblHITIndexWeightTable[],4,FALSE),"") | O12: =VLOOKUP(tblRiskRegister32[[#This Row],[Asset Class]],tblInherentImpacts30[],2,FALSE) -> 0 | P12: =VLOOKUP(tblRiskRegister32[[#This Row],[Asset Class]],tblInherentImpacts30[],3,FALSE) -> 0 | Q12: =VLOOKUP(tblRiskRegister32[[#This Row],[Asset Class]],tblInherentImpacts30[],4,FALSE) -> 0 | R12: =VLOOKUP(tblRiskRegister32[[#This Row],[Asset Class]],tblInherentImpacts30[],5,FALSE) -> 0 | S12: =IFERROR(MAX(tblRiskRegister32[[#This Row],[Impact to Mission]:[Impact to Obligations]])*tblRiskRegister32[[#This Row],[Expectancy Score]],"") | T12: =tblRiskRegister32[[#This Row],[Risk Score]] | V12: 1.2 | W12: Address Unauthorized Assets | X12: Ensure that a process exists to address unauthorized assets on a weekly basis. The enterprise may choose to remove the asset from the network, deny the asset from connecting remotely to the network, or quarantine the asset. | AA12: =IFERROR(VLOOKUP(10*tblRiskRegister32[[#This Row],[Risk Treatment Safeguard Maturity Score]]+tblRiskRegister32[[#This Row],[VCDB Index]],tblHITIndexWeightTable[],4,FALSE),"") | AB12: =VLOOKUP(tblRiskRegister32[[#This Row],[Asset Class]],tblInherentImpacts30[],2,FALSE) -> 0 | AC12: =VLOOKUP(tblRiskRegister32[[#This Row],[Asset Class]],tblInherentImpacts30[],3,FALSE) -> 0 | AD12: =VLOOKUP(tblRiskRegister32[[#This Row],[Asset Class]],tblInherentImpacts30[],4,FALSE) -> 0 | AE12: =VLOOKUP(tblRiskRegister32[[#This Row],[Asset Class]],tblInherentImpacts30[],5,FALSE) -> 0 | AF12: =IFERROR(MAX(tblRiskRegister32[[#This Row],[Risk Treatment Safeguard Impact to Mission]:[Risk Treatment Safeguard Impact to Obligations]])*tblRiskRegister32[[#This Row],[Risk Treatment Safeguard Expectancy Score]],"") | AG12: =IF(tblRiskRegister32[[#This Row],[Risk Score]]>=AcceptableRisk,IF(tblRiskRegister32[[#This Row],[Risk Treatment Safeguard Risk Score]]<AcceptableRisk, IF(tblRiskRegister32[[#This Row],[Risk Treatment Safeguard Risk Score]]<tblRiskRegister32[[#This Row],[Risk Score]],"Yes","No"),"No"),"Yes") -> No | AL12: =SUMIF(tblRiskRegister32[[#All],[Implementation Year]],"="&tblCostImpacts33[[#This Row],[Year]],tblRiskRegister32[[#All],[Risk Treatment Safeguard Cost]]) -> 0 | AM12: 2026 | AN12: =IF(tblCostImpacts33[[#This Row],[Impact to Financial Objectives]]<='2. Enterprise Parameters'!$F$13,"Yes","No") -> Yes
B13: Devices | D13: 1.3 | E13: Utilize an Active Discovery Tool | G13: x | H13: Detect | M13: =IFERROR(VLOOKUP(tblRiskRegister32[[#This Row],[Asset Class]],tblVCDBIndex[],4,FALSE),"") -> 4 | N13: =IFERROR(VLOOKUP(10*tblRiskRegister32[[#This Row],[Safeguard Maturity Score]]+tblRiskRegister32[[#This Row],[VCDB Index]],tblHITIndexWeightTable[],4,FALSE),"") | O13: =VLOOKUP(tblRiskRegister32[[#This Row],[Asset Class]],tblInherentImpacts30[],2,FALSE) -> 0 | P13: =VLOOKUP(tblRiskRegister32[[#This Row],[Asset Class]],tblInherentImpacts30[],3,FALSE) -> 0 | Q13: =VLOOKUP(tblRiskRegister32[[#This Row],[Asset Class]],tblInherentImpacts30[],4,FALSE) -> 0 | R13: =VLOOKUP(tblRiskRegister32[[#This Row],[Asset Class]],tblInherentImpacts30[],5,FALSE) -> 0 | S13: =IFERROR(MAX(tblRiskRegister32[[#This Row],[Impact to Mission]:[Impact to Obligations]])*tblRiskRegister32[[#This Row],[Expectancy Score]],"") | T13: =tblRiskRegister32[[#This Row],[Risk Score]] | V13: 1.3 | W13: Utilize an Active Discovery Tool | X13: Utilize an active discovery tool to identify assets connected to the enterprise’s network. Configure the active discovery tool to execute daily, or more frequently. | AA13: =IFERROR(VLOOKUP(10*tblRiskRegister32[[#This Row],[Risk Treatment Safeguard Maturity Score]]+tblRiskRegister32[[#This Row],[VCDB Index]],tblHITIndexWeightTable[],4,FALSE),"") | AB13: =VLOOKUP(tblRiskRegister32[[#This Row],[Asset Class]],tblInherentImpacts30[],2,FALSE) -> 0 | AC13: =VLOOKUP(tblRiskRegister32[[#This Row],[Asset Class]],tblInherentImpacts30[],3,FALSE) -> 0 | AD13: =VLOOKUP(tblRiskRegister32[[#This Row],[Asset Class]],tblInherentImpacts30[],4,FALSE) -> 0 | AE13: =VLOOKUP(tblRiskRegister32[[#This Row],[Asset Class]],tblInherentImpacts30[],5,FALSE) -> 0 | AF13: =IFERROR(MAX(tblRiskRegister32[[#This Row],[Risk Treatment Safeguard Impact to Mission]:[Risk Treatment Safeguard Impact to Obligations]])*tblRiskRegister32[[#This Row],[Risk Treatment Safeguard Expectancy Score]],"") | AG13: =IF(tblRiskRegister32[[#This Row],[Risk Score]]>=AcceptableRisk,IF(tblRiskRegister32[[#This Row],[Risk Treatment Safeguard Risk Score]]<AcceptableRisk, IF(tblRiskRegister32[[#This Row],[Risk Treatment Safeguard Risk Score]]<tblRiskRegister32[[#This Row],[Risk Score]],"Yes","No"),"No"),"Yes") -> No | AL13: =SUMIF(tblRiskRegister32[[#All],[Implementation Year]],"="&tblCostImpacts33[[#This Row],[Year]],tblRiskRegister32[[#All],[Risk Treatment Safeguard Cost]]) -> 0 | AM13: 2027 | AN13: =IF(tblCostImpacts33[[#This Row],[Impact to Financial Objectives]]<='2. Enterprise Parameters'!$F$13,"Yes","No") -> Yes
B14: Devices | D14: 1.4 | E14: Use Dynamic Host Configuration Protocol (DHCP) Logging to Update Enterprise Asset Inventory | G14: x | H14: Identify | M14: =IFERROR(VLOOKUP(tblRiskRegister32[[#This Row],[Asset Class]],tblVCDBIndex[],4,FALSE),"") -> 4 | N14: =IFERROR(VLOOKUP(10*tblRiskRegister32[[#This Row],[Safeguard Maturity Score]]+tblRiskRegister32[[#This Row],[VCDB Index]],tblHITIndexWeightTable[],4,FALSE),"") | O14: =VLOOKUP(tblRiskRegister32[[#This Row],[Asset Class]],tblInherentImpacts30[],2,FALSE) -> 0 | P14: =VLOOKUP(tblRiskRegister32[[#This Row],[Asset Class]],tblInherentImpacts30[],3,FALSE) -> 0 | Q14: =VLOOKUP(tblRiskRegister32[[#This Row],[Asset Class]],tblInherentImpacts30[],4,FALSE) -> 0 | R14: =VLOOKUP(tblRiskRegister32[[#This Row],[Asset Class]],tblInherentImpacts30[],5,FALSE) -> 0 | S14: =IFERROR(MAX(tblRiskRegister32[[#This Row],[Impact to Mission]:[Impact to Obligations]])*tblRiskRegister32[[#This Row],[Expectancy Score]],"") | T14: =tblRiskRegister32[[#This Row],[Risk Score]] | V14: 1.4 | W14: Use Dynamic Host Configuration Protocol (DHCP) Logging to Update Enterprise Asset Inventory | X14: Use DHCP logging on all DHCP servers or Internet Protocol (IP) address management tools to update the enterprise’s asset inventory. Review and use logs to update the enterprise’s asset inventory weekly, or more frequently. | AA14: =IFERROR(VLOOKUP(10*tblRiskRegister32[[#This Row],[Risk Treatment Safeguard Maturity Score]]+tblRiskRegister32[[#This Row],[VCDB Index]],tblHITIndexWeightTable[],4,FALSE),"") | AB14: =VLOOKUP(tblRiskRegister32[[#This Row],[Asset Class]],tblInherentImpacts30[],2,FALSE) -> 0 | AC14: =VLOOKUP(tblRiskRegister32[[#This Row],[Asset Class]],tblInherentImpacts30[],3,FALSE) -> 0 | AD14: =VLOOKUP(tblRiskRegister32[[#This Row],[Asset Class]],tblInherentImpacts30[],4,FALSE) -> 0 | AE14: =VLOOKUP(tblRiskRegister32[[#This Row],[Asset Class]],tblInherentImpacts30[],5,FALSE) -> 0 | AF14: =IFERROR(MAX(tblRiskRegister32[[#This Row],[Risk Treatment Safeguard Impact to Mission]:[Risk Treatment Safeguard Impact to Obligations]])*tblRiskRegister32[[#This Row],[Risk Treatment Safeguard Expectancy Score]],"") | AG14: =IF(tblRiskRegister32[[#This Row],[Risk Score]]>=AcceptableRisk,IF(tblRiskRegister32[[#This Row],[Risk Treatment Safeguard Risk Score]]<AcceptableRisk, IF(tblRiskRegister32[[#This Row],[Risk Treatment Safeguard Risk Score]]<tblRiskRegister32[[#This Row],[Risk Score]],"Yes","No"),"No"),"Yes") -> No | AL14: =SUMIF(tblRiskRegister32[[#All],[Implementation Year]],"="&tblCostImpacts33[[#This Row],[Year]],tblRiskRegister32[[#All],[Risk Treatment Safeguard Cost]]) -> 0 | AM14: 2028 | AN14: =IF(tblCostImpacts33[[#This Row],[Impact to Financial Objectives]]<='2. Enterprise Parameters'!$F$13,"Yes","No") -> Yes
B15: Software | D15: 2.1 | E15: Establish and Maintain a Software Inventory | F15: x | G15: x | H15: Identify | M15: =IFERROR(VLOOKUP(tblRiskRegister32[[#This Row],[Asset Class]],tblVCDBIndex[],4,FALSE),"") -> 2 | N15: =IFERROR(VLOOKUP(10*tblRiskRegister32[[#This Row],[Safeguard Maturity Score]]+tblRiskRegister32[[#This Row],[VCDB Index]],tblHITIndexWeightTable[],4,FALSE),"") | O15: =VLOOKUP(tblRiskRegister32[[#This Row],[Asset Class]],tblInherentImpacts30[],2,FALSE) -> 0 | P15: =VLOOKUP(tblRiskRegister32[[#This Row],[Asset Class]],tblInherentImpacts30[],3,FALSE) -> 0 | Q15: =VLOOKUP(tblRiskRegister32[[#This Row],[Asset Class]],tblInherentImpacts30[],4,FALSE) -> 0 | R15: =VLOOKUP(tblRiskRegister32[[#This Row],[Asset Class]],tblInherentImpacts30[],5,FALSE) -> 0 | S15: =IFERROR(MAX(tblRiskRegister32[[#This Row],[Impact to Mission]:[Impact to Obligations]])*tblRiskRegister32[[#This Row],[Expectancy Score]],"") | T15: =tblRiskRegister32[[#This Row],[Risk Score]] | V15: 2.1 | W15: Establish and Maintain a Software Inventory | X15: Establish and maintain a detailed inventory of all licensed software installed on enterprise assets. The software inventory must document the title, publisher, initial install/use date, and business purpose for each entry; where appropriate, include the Uniform Resource Locator (URL), app store(s), version(s), deployment mechanism, decommission date, and number of licenses. Review and update the software inventory bi-annually, or more frequently. | AA15: =IFERROR(VLOOKUP(10*tblRiskRegister32[[#This Row],[Risk Treatment Safeguard Maturity Score]]+tblRiskRegister32[[#This Row],[VCDB Index]],tblHITIndexWeightTable[],4,FALSE),"") | AB15: =VLOOKUP(tblRiskRegister32[[#This Row],[Asset Class]],tblInherentImpacts30[],2,FALSE) -> 0 | AC15: =VLOOKUP(tblRiskRegister32[[#This Row],[Asset Class]],tblInherentImpacts30[],3,FALSE) -> 0 | AD15: =VLOOKUP(tblRiskRegister32[[#This Row],[Asset Class]],tblInherentImpacts30[],4,FALSE) -> 0 | AE15: =VLOOKUP(tblRiskRegister32[[#This Row],[Asset Class]],tblInherentImpacts30[],5,FALSE) -> 0 | AF15: =IFERROR(MAX(tblRiskRegister32[[#This Row],[Risk Treatment Safeguard Impact to Mission]:[Risk Treatment Safeguard Impact to Obligations]])*tblRiskRegister32[[#This Row],[Risk Treatment Safeguard Expectancy Score]],"") | AG15: =IF(tblRiskRegister32[[#This Row],[Risk Score]]>=AcceptableRisk,IF(tblRiskRegister32[[#This Row],[Risk Treatment Safeguard Risk Score]]<AcceptableRisk, IF(tblRiskRegister32[[#This Row],[Risk Treatment Safeguard Risk Score]]<tblRiskRegister32[[#This Row],[Risk Score]],"Yes","No"),"No"),"Yes") -> No | AL15: =SUMIF(tblRiskRegister32[[#All],[Implementation Year]],"="&tblCostImpacts33[[#This Row],[Year]],tblRiskRegister32[[#All],[Risk Treatment Safeguard Cost]]) -> 0 | AM15: 2029 | AN15: =IF(tblCostImpacts33[[#This Row],[Impact to Financial Objectives]]<='2. Enterprise Parameters'!$F$13,"Yes","No") -> Yes
B16: Software | D16: 2.2 | E16: Ensure Authorized Software is Currently Supported | F16: x | G16: x | H16: Identify | M16: =IFERROR(VLOOKUP(tblRiskRegister32[[#This Row],[Asset Class]],tblVCDBIndex[],4,FALSE),"") -> 2 | N16: =IFERROR(VLOOKUP(10*tblRiskRegister32[[#This Row],[Safeguard Maturity Score]]+tblRiskRegister32[[#This Row],[VCDB Index]],tblHITIndexWeightTable[],4,FALSE),"") | O16: =VLOOKUP(tblRiskRegister32[[#This Row],[Asset Class]],tblInherentImpacts30[],2,FALSE) -> 0 | P16: =VLOOKUP(tblRiskRegister32[[#This Row],[Asset Class]],tblInherentImpacts30[],3,FALSE) -> 0 | Q16: =VLOOKUP(tblRiskRegister32[[#This Row],[Asset Class]],tblInherentImpacts30[],4,FALSE) -> 0 | R16: =VLOOKUP(tblRiskRegister32[[#This Row],[Asset Class]],tblInherentImpacts30[],5,FALSE) -> 0 | S16: =IFERROR(MAX(tblRiskRegister32[[#This Row],[Impact to Mission]:[Impact to Obligations]])*tblRiskRegister32[[#This Row],[Expectancy Score]],"") | T16: =tblRiskRegister32[[#This Row],[Risk Score]] | V16: 2.2 | W16: Ensure Authorized Software is Currently Supported | X16: Ensure that only currently supported software is designated as authorized in the software inventory for enterprise assets. If software is unsupported, yet necessary for the fulfillment of the enterprise’s mission, document an exception detailing mitigating controls and residual risk acceptance. For any unsupported software without an exception documentation, designate as unauthorized. Review the software list to verify software support at least monthly, or more frequently. | AA16: =IFERROR(VLOOKUP(10*tblRiskRegister32[[#This Row],[Risk Treatment Safeguard Maturity Score]]+tblRiskRegister32[[#This Row],[VCDB Index]],tblHITIndexWeightTable[],4,FALSE),"") | AB16: =VLOOKUP(tblRiskRegister32[[#This Row],[Asset Class]],tblInherentImpacts30[],2,FALSE) -> 0 | AC16: =VLOOKUP(tblRiskRegister32[[#This Row],[Asset Class]],tblInherentImpacts30[],3,FALSE) -> 0 | AD16: =VLOOKUP(tblRiskRegister32[[#This Row],[Asset Class]],tblInherentImpacts30[],4,FALSE) -> 0 | AE16: =VLOOKUP(tblRiskRegister32[[#This Row],[Asset Class]],tblInherentImpacts30[],5,FALSE) -> 0 | AF16: =IFERROR(MAX(tblRiskRegister32[[#This Row],[Risk Treatment Safeguard Impact to Mission]:[Risk Treatment Safeguard Impact to Obligations]])*tblRiskRegister32[[#This Row],[Risk Treatment Safeguard Expectancy Score]],"") | AG16: =IF(tblRiskRegister32[[#This Row],[Risk Score]]>=AcceptableRisk,IF(tblRiskRegister32[[#This Row],[Risk Treatment Safeguard Risk Score]]<AcceptableRisk, IF(tblRiskRegister32[[#This Row],[Risk Treatment Safeguard Risk Score]]<tblRiskRegister32[[#This Row],[Risk Score]],"Yes","No"),"No"),"Yes") -> No | AL16: =SUMIF(tblRiskRegister32[[#All],[Implementation Year]],"="&tblCostImpacts33[[#This Row],[Year]],tblRiskRegister32[[#All],[Risk Treatment Safeguard Cost]]) -> 0 | AM16: 2030 | AN16: =IF(tblCostImpacts33[[#This Row],[Impact to Financial Objectives]]<='2. Enterprise Parameters'!$F$13,"Yes","No") -> Yes
B17: Software | D17: 2.3 | E17: Address Unauthorized Software | F17: x | G17: x | H17: Respond | M17: =IFERROR(VLOOKUP(tblRiskRegister32[[#This Row],[Asset Class]],tblVCDBIndex[],4,FALSE),"") -> 2 | N17: =IFERROR(VLOOKUP(10*tblRiskRegister32[[#This Row],[Safeguard Maturity Score]]+tblRiskRegister32[[#This Row],[VCDB Index]],tblHITIndexWeightTable[],4,FALSE),"") | O17: =VLOOKUP(tblRiskRegister32[[#This Row],[Asset Class]],tblInherentImpacts30[],2,FALSE) -> 0 | P17: =VLOOKUP(tblRiskRegister32[[#This Row],[Asset Class]],tblInherentImpacts30[],3,FALSE) -> 0 | Q17: =VLOOKUP(tblRiskRegister32[[#This Row],[Asset Class]],tblInherentImpacts30[],4,FALSE) -> 0 | R17: =VLOOKUP(tblRiskRegister32[[#This Row],[Asset Class]],tblInherentImpacts30[],5,FALSE) -> 0 | S17: =IFERROR(MAX(tblRiskRegister32[[#This Row],[Impact to Mission]:[Impact to Obligations]])*tblRiskRegister32[[#This Row],[Expectancy Score]],"") | T17: =tblRiskRegister32[[#This Row],[Risk Score]] | V17: 2.3 | W17: Address Unauthorized Software | X17: Ensure that unauthorized software is either removed from use on enterprise assets or receives a documented exception. Review monthly, or more frequently. | AA17: =IFERROR(VLOOKUP(10*tblRiskRegister32[[#This Row],[Risk Treatment Safeguard Maturity Score]]+tblRiskRegister32[[#This Row],[VCDB Index]],tblHITIndexWeightTable[],4,FALSE),"") | AB17: =VLOOKUP(tblRiskRegister32[[#This Row],[Asset Class]],tblInherentImpacts30[],2,FALSE) -> 0 | AC17: =VLOOKUP(tblRiskRegister32[[#This Row],[Asset Class]],tblInherentImpacts30[],3,FALSE) -> 0 | AD17: =VLOOKUP(tblRiskRegister32[[#This Row],[Asset Class]],tblInherentImpacts30[],4,FALSE) -> 0 | AE17: =VLOOKUP(tblRiskRegister32[[#This Row],[Asset Class]],tblInherentImpacts30[],5,FALSE) -> 0 | AF17: =IFERROR(MAX(tblRiskRegister32[[#This Row],[Risk Treatment Safeguard Impact to Mission]:[Risk Treatment Safeguard Impact to Obligations]])*tblRiskRegister32[[#This Row],[Risk Treatment Safeguard Expectancy Score]],"") | AG17: =IF(tblRiskRegister32[[#This Row],[Risk Score]]>=AcceptableRisk,IF(tblRiskRegister32[[#This Row],[Risk Treatment Safeguard Risk Score]]<AcceptableRisk, IF(tblRiskRegister32[[#This Row],[Risk Treatment Safeguard Risk Score]]<tblRiskRegister32[[#This Row],[Risk Score]],"Yes","No"),"No"),"Yes") -> No | AL17: =SUMIF(tblRiskRegister32[[#All],[Implementation Year]],"="&tblCostImpacts33[[#This Row],[Year]],tblRiskRegister32[[#All],[Risk Treatment Safeguard Cost]]) -> 0 | AM17: 2031 | AN17: =IF(tblCostImpacts33[[#This Row],[Impact to Financial Objectives]]<='2. Enterprise Parameters'!$F$13,"Yes","No") -> Yes
B18: Software | D18: 2.4 | E18: Utilize Automated Software Inventory Tools | G18: x | H18: Detect | M18: =IFERROR(VLOOKUP(tblRiskRegister32[[#This Row],[Asset Class]],tblVCDBIndex[],4,FALSE),"") -> 2 | N18: =IFERROR(VLOOKUP(10*tblRiskRegister32[[#This Row],[Safeguard Maturity Score]]+tblRiskRegister32[[#This Row],[VCDB Index]],tblHITIndexWeightTable[],4,FALSE),"") | O18: =VLOOKUP(tblRiskRegister32[[#This Row],[Asset Class]],tblInherentImpacts30[],2,FALSE) -> 0 | P18: =VLOOKUP(tblRiskRegister32[[#This Row],[Asset Class]],tblInherentImpacts30[],3,FALSE) -> 0 | Q18: =VLOOKUP(tblRiskRegister32[[#This Row],[Asset Class]],tblInherentImpacts30[],4,FALSE) -> 0 | R18: =VLOOKUP(tblRiskRegister32[[#This Row],[Asset Class]],tblInherentImpacts30[],5,FALSE) -> 0 | S18: =IFERROR(MAX(tblRiskRegister32[[#This Row],[Impact to Mission]:[Impact to Obligations]])*tblRiskRegister32[[#This Row],[Expectancy Score]],"") | T18: =tblRiskRegister32[[#This Row],[Risk Score]] | V18: 2.4 | W18: Utilize Automated Software Inventory Tools | X18: Utilize software inventory tools, when possible, throughout the enterprise to automate the discovery and documentation of installed software. | AA18: =IFERROR(VLOOKUP(10*tblRiskRegister32[[#This Row],[Risk Treatment Safeguard Maturity Score]]+tblRiskRegister32[[#This Row],[VCDB Index]],tblHITIndexWeightTable[],4,FALSE),"") | AB18: =VLOOKUP(tblRiskRegister32[[#This Row],[Asset Class]],tblInherentImpacts30[],2,FALSE) -> 0 | AC18: =VLOOKUP(tblRiskRegister32[[#This Row],[Asset Class]],tblInherentImpacts30[],3,FALSE) -> 0 | AD18: =VLOOKUP(tblRiskRegister32[[#This Row],[Asset Class]],tblInherentImpacts30[],4,FALSE) -> 0 | AE18: =VLOOKUP(tblRiskRegister32[[#This Row],[Asset Class]],tblInherentImpacts30[],5,FALSE) -> 0 | AF18: =IFERROR(MAX(tblRiskRegister32[[#This Row],[Risk Treatment Safeguard Impact to Mission]:[Risk Treatment Safeguard Impact to Obligations]])*tblRiskRegister32[[#This Row],[Risk Treatment Safeguard Expectancy Score]],"") | AG18: =IF(tblRiskRegister32[[#This Row],[Risk Score]]>=AcceptableRisk,IF(tblRiskRegister32[[#This Row],[Risk Treatment Safeguard Risk Score]]<AcceptableRisk, IF(tblRiskRegister32[[#This Row],[Risk Treatment Safeguard Risk Score]]<tblRiskRegister32[[#This Row],[Risk Score]],"Yes","No"),"No"),"Yes") -> No | AL18: =SUMIF(tblRiskRegister32[[#All],[Implementation Year]],"="&tblCostImpacts33[[#This Row],[Year]],tblRiskRegister32[[#All],[Risk Treatment Safeguard Cost]]) -> 0 | AM18: 2032 | AN18: =IF(tblCostImpacts33[[#This Row],[Impact to Financial Objectives]]<='2. Enterprise Parameters'!$F$13,"Yes","No") -> Yes
B19: Software | D19: 2.5 | E19: Allowlist Authorized Software | G19: x | H19: Protect | M19: =IFERROR(VLOOKUP(tblRiskRegister32[[#This Row],[Asset Class]],tblVCDBIndex[],4,FALSE),"") -> 2 | N19: =IFERROR(VLOOKUP(10*tblRiskRegister32[[#This Row],[Safeguard Maturity Score]]+tblRiskRegister32[[#This Row],[VCDB Index]],tblHITIndexWeightTable[],4,FALSE),"") | O19: =VLOOKUP(tblRiskRegister32[[#This Row],[Asset Class]],tblInherentImpacts30[],2,FALSE) -> 0 | P19: =VLOOKUP(tblRiskRegister32[[#This Row],[Asset Class]],tblInherentImpacts30[],3,FALSE) -> 0 | Q19: =VLOOKUP(tblRiskRegister32[[#This Row],[Asset Class]],tblInherentImpacts30[],4,FALSE) -> 0 | R19: =VLOOKUP(tblRiskRegister32[[#This Row],[Asset Class]],tblInherentImpacts30[],5,FALSE) -> 0 | S19: =IFERROR(MAX(tblRiskRegister32[[#This Row],[Impact to Mission]:[Impact to Obligations]])*tblRiskRegister32[[#This Row],[Expectancy Score]],"") | T19: =tblRiskRegister32[[#This Row],[Risk Score]] | V19: 2.5 | W19: Allowlist Authorized Software | X19: Use technical controls, such as application allowlisting, to ensure that only authorized software can execute or be accessed. Reassess bi-annually, or more frequently. | AA19: =IFERROR(VLOOKUP(10*tblRiskRegister32[[#This Row],[Risk Treatment Safeguard Maturity Score]]+tblRiskRegister32[[#This Row],[VCDB Index]],tblHITIndexWeightTable[],4,FALSE),"") | AB19: =VLOOKUP(tblRiskRegister32[[#This Row],[Asset Class]],tblInherentImpacts30[],2,FALSE) -> 0 | AC19: =VLOOKUP(tblRiskRegister32[[#This Row],[Asset Class]],tblInherentImpacts30[],3,FALSE) -> 0 | AD19: =VLOOKUP(tblRiskRegister32[[#This Row],[Asset Class]],tblInherentImpacts30[],4,FALSE) -> 0 | AE19: =VLOOKUP(tblRiskRegister32[[#This Row],[Asset Class]],tblInherentImpacts30[],5,FALSE) -> 0 | AF19: =IFERROR(MAX(tblRiskRegister32[[#This Row],[Risk Treatment Safeguard Impact to Mission]:[Risk Treatment Safeguard Impact to Obligations]])*tblRiskRegister32[[#This Row],[Risk Treatment Safeguard Expectancy Score]],"") | AG19: =IF(tblRiskRegister32[[#This Row],[Risk Score]]>=AcceptableRisk,IF(tblRiskRegister32[[#This Row],[Risk Treatment Safeguard Risk Score]]<AcceptableRisk, IF(tblRiskRegister32[[#This Row],[Risk Treatment Safeguard Risk Score]]<tblRiskRegister32[[#This Row],[Risk Score]],"Yes","No"),"No"),"Yes") -> No | AL19: =SUMIF(tblRiskRegister32[[#All],[Implementation Year]],"="&tblCostImpacts33[[#This Row],[Year]],tblRiskRegister32[[#All],[Risk Treatment Safeguard Cost]]) -> 0 | AM19: 2033 | AN19: =IF(tblCostImpacts33[[#This Row],[Impact to Financial Objectives]]<='2. Enterprise Parameters'!$F$13,"Yes","No") -> Yes
B20: Software | D20: 2.6 | E20: Allowlist Authorized Libraries | G20: x | H20: Protect | M20: =IFERROR(VLOOKUP(tblRiskRegister32[[#This Row],[Asset Class]],tblVCDBIndex[],4,FALSE),"") -> 2 | N20: =IFERROR(VLOOKUP(10*tblRiskRegister32[[#This Row],[Safeguard Maturity Score]]+tblRiskRegister32[[#This Row],[VCDB Index]],tblHITIndexWeightTable[],4,FALSE),"") | O20: =VLOOKUP(tblRiskRegister32[[#This Row],[Asset Class]],tblInherentImpacts30[],2,FALSE) -> 0 | P20: =VLOOKUP(tblRiskRegister32[[#This Row],[Asset Class]],tblInherentImpacts30[],3,FALSE) -> 0 | Q20: =VLOOKUP(tblRiskRegister32[[#This Row],[Asset Class]],tblInherentImpacts30[],4,FALSE) -> 0 | R20: =VLOOKUP(tblRiskRegister32[[#This Row],[Asset Class]],tblInherentImpacts30[],5,FALSE) -> 0 | S20: =IFERROR(MAX(tblRiskRegister32[[#This Row],[Impact to Mission]:[Impact to Obligations]])*tblRiskRegister32[[#This Row],[Expectancy Score]],"") | T20: =tblRiskRegister32[[#This Row],[Risk Score]] | V20: 4.1 | W20: Establish and Maintain a Secure Configuration Process | X20: Use technical controls to ensure that only authorized software libraries, such as specific .dll, .ocx, and .so files, are allowed to load into a system process. Block unauthorized libraries from loading into a system process. Reassess bi-annually, or more frequently. | AA20: =IFERROR(VLOOKUP(10*tblRiskRegister32[[#This Row],[Risk Treatment Safeguard Maturity Score]]+tblRiskRegister32[[#This Row],[VCDB Index]],tblHITIndexWeightTable[],4,FALSE),"") | AB20: =VLOOKUP(tblRiskRegister32[[#This Row],[Asset Class]],tblInherentImpacts30[],2,FALSE) -> 0 | AC20: =VLOOKUP(tblRiskRegister32[[#This Row],[Asset Class]],tblInherentImpacts30[],3,FALSE) -> 0 | AD20: =VLOOKUP(tblRiskRegister32[[#This Row],[Asset Class]],tblInherentImpacts30[],4,FALSE) -> 0 | AE20: =VLOOKUP(tblRiskRegister32[[#This Row],[Asset Class]],tblInherentImpacts30[],5,FALSE) -> 0 | AF20: =IFERROR(MAX(tblRiskRegister32[[#This Row],[Risk Treatment Safeguard Impact to Mission]:[Risk Treatment Safeguard Impact to Obligations]])*tblRiskRegister32[[#This Row],[Risk Treatment Safeguard Expectancy Score]],"") | AG20: =IF(tblRiskRegister32[[#This Row],[Risk Score]]>=AcceptableRisk,IF(tblRiskRegister32[[#This Row],[Risk Treatment Safeguard Risk Score]]<AcceptableRisk, IF(tblRiskRegister32[[#This Row],[Risk Treatment Safeguard Risk Score]]<tblRiskRegister32[[#This Row],[Risk Score]],"Yes","No"),"No"),"Yes") -> No | AL20: =SUMIF(tblRiskRegister32[[#All],[Implementation Year]],"="&tblCostImpacts33[[#This Row],[Year]],tblRiskRegister32[[#All],[Risk Treatment Safeguard Cost]]) -> 0 | AM20: 2034 | AN20: =IF(tblCostImpacts33[[#This Row],[Impact to Financial Objectives]]<='2. Enterprise Parameters'!$F$13,"Yes","No") -> Yes
B21: Data | D21: 3.1 | E21: Establish and Maintain a Data Management Process | F21: x | G21: x | H21: Govern | M21: =IFERROR(VLOOKUP(tblRiskRegister32[[#This Row],[Asset Class]],tblVCDBIndex[],4,FALSE),"") -> 2 | N21: =IFERROR(VLOOKUP(10*tblRiskRegister32[[#This Row],[Safeguard Maturity Score]]+tblRiskRegister32[[#This Row],[VCDB Index]],tblHITIndexWeightTable[],4,FALSE),"") | O21: =VLOOKUP(tblRiskRegister32[[#This Row],[Asset Class]],tblInherentImpacts30[],2,FALSE) -> 0 | P21: =VLOOKUP(tblRiskRegister32[[#This Row],[Asset Class]],tblInherentImpacts30[],3,FALSE) -> 0 | Q21: =VLOOKUP(tblRiskRegister32[[#This Row],[Asset Class]],tblInherentImpacts30[],4,FALSE) -> 0 | R21: =VLOOKUP(tblRiskRegister32[[#This Row],[Asset Class]],tblInherentImpacts30[],5,FALSE) -> 0 | S21: =IFERROR(MAX(tblRiskRegister32[[#This Row],[Impact to Mission]:[Impact to Obligations]])*tblRiskRegister32[[#This Row],[Expectancy Score]],"") | T21: =tblRiskRegister32[[#This Row],[Risk Score]] | V21: 3.1 | W21: Establish and Maintain a Data Management Process | X21: Establish and maintain a documented data management process. In the process, address data sensitivity, data owner, handling of data, data retention limits, and disposal requirements, based on sensitivity and retention standards for the enterprise. Review and update documentation annually, or when significant enterprise changes occur that could impact this Safeguard. | AA21: =IFERROR(VLOOKUP(10*tblRiskRegister32[[#This Row],[Risk Treatment Safeguard Maturity Score]]+tblRiskRegister32[[#This Row],[VCDB Index]],tblHITIndexWeightTable[],4,FALSE),"") | AB21: =VLOOKUP(tblRiskRegister32[[#This Row],[Asset Class]],tblInherentImpacts30[],2,FALSE) -> 0 | AC21: =VLOOKUP(tblRiskRegister32[[#This Row],[Asset Class]],tblInherentImpacts30[],3,FALSE) -> 0 | AD21: =VLOOKUP(tblRiskRegister32[[#This Row],[Asset Class]],tblInherentImpacts30[],4,FALSE) -> 0 | AE21: =VLOOKUP(tblRiskRegister32[[#This Row],[Asset Class]],tblInherentImpacts30[],5,FALSE) -> 0 | AF21: =IFERROR(MAX(tblRiskRegister32[[#This Row],[Risk Treatment Safeguard Impact to Mission]:[Risk Treatment Safeguard Impact to Obligations]])*tblRiskRegister32[[#This Row],[Risk Treatment Safeguard Expectancy Score]],"") | AG21: =IF(tblRiskRegister32[[#This Row],[Risk Score]]>=AcceptableRisk,IF(tblRiskRegister32[[#This Row],[Risk Treatment Safeguard Risk Score]]<AcceptableRisk, IF(tblRiskRegister32[[#This Row],[Risk Treatment Safeguard Risk Score]]<tblRiskRegister32[[#This Row],[Risk Score]],"Yes","No"),"No"),"Yes") -> No
B22: Data | D22: 3.2 | E22: Establish and Maintain a Data Inventory | F22: x | G22: x | H22: Identify | M22: =IFERROR(VLOOKUP(tblRiskRegister32[[#This Row],[Asset Class]],tblVCDBIndex[],4,FALSE),"") -> 2 | N22: =IFERROR(VLOOKUP(10*tblRiskRegister32[[#This Row],[Safeguard Maturity Score]]+tblRiskRegister32[[#This Row],[VCDB Index]],tblHITIndexWeightTable[],4,FALSE),"") | O22: =VLOOKUP(tblRiskRegister32[[#This Row],[Asset Class]],tblInherentImpacts30[],2,FALSE) -> 0 | P22: =VLOOKUP(tblRiskRegister32[[#This Row],[Asset Class]],tblInherentImpacts30[],3,FALSE) -> 0 | Q22: =VLOOKUP(tblRiskRegister32[[#This Row],[Asset Class]],tblInherentImpacts30[],4,FALSE) -> 0 | R22: =VLOOKUP(tblRiskRegister32[[#This Row],[Asset Class]],tblInherentImpacts30[],5,FALSE) -> 0 | S22: =IFERROR(MAX(tblRiskRegister32[[#This Row],[Impact to Mission]:[Impact to Obligations]])*tblRiskRegister32[[#This Row],[Expectancy Score]],"") | T22: =tblRiskRegister32[[#This Row],[Risk Score]] | V22: 3.2 | W22: Establish and Maintain a Data Inventory | X22: Establish and maintain a data inventory based on the enterprise’s data management process. Inventory sensitive data, at a minimum. Review and update inventory annually, at a minimum, with a priority on sensitive data. | AA22: =IFERROR(VLOOKUP(10*tblRiskRegister32[[#This Row],[Risk Treatment Safeguard Maturity Score]]+tblRiskRegister32[[#This Row],[VCDB Index]],tblHITIndexWeightTable[],4,FALSE),"") | AB22: =VLOOKUP(tblRiskRegister32[[#This Row],[Asset Class]],tblInherentImpacts30[],2,FALSE) -> 0 | AC22: =VLOOKUP(tblRiskRegister32[[#This Row],[Asset Class]],tblInherentImpacts30[],3,FALSE) -> 0 | AD22: =VLOOKUP(tblRiskRegister32[[#This Row],[Asset Class]],tblInherentImpacts30[],4,FALSE) -> 0 | AE22: =VLOOKUP(tblRiskRegister32[[#This Row],[Asset Class]],tblInherentImpacts30[],5,FALSE) -> 0 | AF22: =IFERROR(MAX(tblRiskRegister32[[#This Row],[Risk Treatment Safeguard Impact to Mission]:[Risk Treatment Safeguard Impact to Obligations]])*tblRiskRegister32[[#This Row],[Risk Treatment Safeguard Expectancy Score]],"") | AG22: =IF(tblRiskRegister32[[#This Row],[Risk Score]]>=AcceptableRisk,IF(tblRiskRegister32[[#This Row],[Risk Treatment Safeguard Risk Score]]<AcceptableRisk, IF(tblRiskRegister32[[#This Row],[Risk Treatment Safeguard Risk Score]]<tblRiskRegister32[[#This Row],[Risk Score]],"Yes","No"),"No"),"Yes") -> No
B23: Data | D23: 3.3 | E23: Configure Data Access Control Lists | F23: x | G23: x | H23: Protect | M23: =IFERROR(VLOOKUP(tblRiskRegister32[[#This Row],[Asset Class]],tblVCDBIndex[],4,FALSE),"") -> 2 | N23: =IFERROR(VLOOKUP(10*tblRiskRegister32[[#This Row],[Safeguard Maturity Score]]+tblRiskRegister32[[#This Row],[VCDB Index]],tblHITIndexWeightTable[],4,FALSE),"") | O23: =VLOOKUP(tblRiskRegister32[[#This Row],[Asset Class]],tblInherentImpacts30[],2,FALSE) -> 0 | P23: =VLOOKUP(tblRiskRegister32[[#This Row],[Asset Class]],tblInherentImpacts30[],3,FALSE) -> 0 | Q23: =VLOOKUP(tblRiskRegister32[[#This Row],[Asset Class]],tblInherentImpacts30[],4,FALSE) -> 0 | R23: =VLOOKUP(tblRiskRegister32[[#This Row],[Asset Class]],tblInherentImpacts30[],5,FALSE) -> 0 | S23: =IFERROR(MAX(tblRiskRegister32[[#This Row],[Impact to Mission]:[Impact to Obligations]])*tblRiskRegister32[[#This Row],[Expectancy Score]],"") | T23: =tblRiskRegister32[[#This Row],[Risk Score]] | V23: 3.3 | W23: Configure Data Access Control Lists | X23: Configure data access control lists based on a user’s need to know. Apply data access control lists, also known as access permissions, to local and remote file systems, databases, and applications. | AA23: =IFERROR(VLOOKUP(10*tblRiskRegister32[[#This Row],[Risk Treatment Safeguard Maturity Score]]+tblRiskRegister32[[#This Row],[VCDB Index]],tblHITIndexWeightTable[],4,FALSE),"") | AB23: =VLOOKUP(tblRiskRegister32[[#This Row],[Asset Class]],tblInherentImpacts30[],2,FALSE) -> 0 | AC23: =VLOOKUP(tblRiskRegister32[[#This Row],[Asset Class]],tblInherentImpacts30[],3,FALSE) -> 0 | AD23: =VLOOKUP(tblRiskRegister32[[#This Row],[Asset Class]],tblInherentImpacts30[],4,FALSE) -> 0 | AE23: =VLOOKUP(tblRiskRegister32[[#This Row],[Asset Class]],tblInherentImpacts30[],5,FALSE) -> 0 | AF23: =IFERROR(MAX(tblRiskRegister32[[#This Row],[Risk Treatment Safeguard Impact to Mission]:[Risk Treatment Safeguard Impact to Obligations]])*tblRiskRegister32[[#This Row],[Risk Treatment Safeguard Expectancy Score]],"") | AG23: =IF(tblRiskRegister32[[#This Row],[Risk Score]]>=AcceptableRisk,IF(tblRiskRegister32[[#This Row],[Risk Treatment Safeguard Risk Score]]<AcceptableRisk, IF(tblRiskRegister32[[#This Row],[Risk Treatment Safeguard Risk Score]]<tblRiskRegister32[[#This Row],[Risk Score]],"Yes","No"),"No"),"Yes") -> No
B24: Data | D24: 3.4 | E24: Enforce Data Retention | F24: x | G24: x | H24: Protect | M24: =IFERROR(VLOOKUP(tblRiskRegister32[[#This Row],[Asset Class]],tblVCDBIndex[],4,FALSE),"") -> 2 | N24: =IFERROR(VLOOKUP(10*tblRiskRegister32[[#This Row],[Safeguard Maturity Score]]+tblRiskRegister32[[#This Row],[VCDB Index]],tblHITIndexWeightTable[],4,FALSE),"") | O24: =VLOOKUP(tblRiskRegister32[[#This Row],[Asset Class]],tblInherentImpacts30[],2,FALSE) -> 0 | P24: =VLOOKUP(tblRiskRegister32[[#This Row],[Asset Class]],tblInherentImpacts30[],3,FALSE) -> 0 | Q24: =VLOOKUP(tblRiskRegister32[[#This Row],[Asset Class]],tblInherentImpacts30[],4,FALSE) -> 0 | R24: =VLOOKUP(tblRiskRegister32[[#This Row],[Asset Class]],tblInherentImpacts30[],5,FALSE) -> 0 | S24: =IFERROR(MAX(tblRiskRegister32[[#This Row],[Impact to Mission]:[Impact to Obligations]])*tblRiskRegister32[[#This Row],[Expectancy Score]],"") | T24: =tblRiskRegister32[[#This Row],[Risk Score]] | V24: 3.4 | W24: Enforce Data Retention | X24: Retain data according to the enterprise’s documented data management process. Data retention must include both minimum and maximum timelines. | AA24: =IFERROR(VLOOKUP(10*tblRiskRegister32[[#This Row],[Risk Treatment Safeguard Maturity Score]]+tblRiskRegister32[[#This Row],[VCDB Index]],tblHITIndexWeightTable[],4,FALSE),"") | AB24: =VLOOKUP(tblRiskRegister32[[#This Row],[Asset Class]],tblInherentImpacts30[],2,FALSE) -> 0 | AC24: =VLOOKUP(tblRiskRegister32[[#This Row],[Asset Class]],tblInherentImpacts30[],3,FALSE) -> 0 | AD24: =VLOOKUP(tblRiskRegister32[[#This Row],[Asset Class]],tblInherentImpacts30[],4,FALSE) -> 0 | AE24: =VLOOKUP(tblRiskRegister32[[#This Row],[Asset Class]],tblInherentImpacts30[],5,FALSE) -> 0 | AF24: =IFERROR(MAX(tblRiskRegister32[[#This Row],[Risk Treatment Safeguard Impact to Mission]:[Risk Treatment Safeguard Impact to Obligations]])*tblRiskRegister32[[#This Row],[Risk Treatment Safeguard Expectancy Score]],"") | AG24: =IF(tblRiskRegister32[[#This Row],[Risk Score]]>=AcceptableRisk,IF(tblRiskRegister32[[#This Row],[Risk Treatment Safeguard Risk Score]]<AcceptableRisk, IF(tblRiskRegister32[[#This Row],[Risk Treatment Safeguard Risk Score]]<tblRiskRegister32[[#This Row],[Risk Score]],"Yes","No"),"No"),"Yes") -> No
B25: Data | D25: 3.5 | E25: Securely Dispose of Data | F25: x | G25: x | H25: Protect | M25: =IFERROR(VLOOKUP(tblRiskRegister32[[#This Row],[Asset Class]],tblVCDBIndex[],4,FALSE),"") -> 2 | N25: =IFERROR(VLOOKUP(10*tblRiskRegister32[[#This Row],[Safeguard Maturity Score]]+tblRiskRegister32[[#This Row],[VCDB Index]],tblHITIndexWeightTable[],4,FALSE),"") | O25: =VLOOKUP(tblRiskRegister32[[#This Row],[Asset Class]],tblInherentImpacts30[],2,FALSE) -> 0 | P25: =VLOOKUP(tblRiskRegister32[[#This Row],[Asset Class]],tblInherentImpacts30[],3,FALSE) -> 0 | Q25: =VLOOKUP(tblRiskRegister32[[#This Row],[Asset Class]],tblInherentImpacts30[],4,FALSE) -> 0 | R25: =VLOOKUP(tblRiskRegister32[[#This Row],[Asset Class]],tblInherentImpacts30[],5,FALSE) -> 0 | S25: =IFERROR(MAX(tblRiskRegister32[[#This Row],[Impact to Mission]:[Impact to Obligations]])*tblRiskRegister32[[#This Row],[Expectancy Score]],"") | T25: =tblRiskRegister32[[#This Row],[Risk Score]] | V25: 3.5 | W25: Securely Dispose of Data | X25: Securely dispose of data as outlined in the enterprise’s documented data management process. Ensure the disposal process and method are commensurate with the data sensitivity. | AA25: =IFERROR(VLOOKUP(10*tblRiskRegister32[[#This Row],[Risk Treatment Safeguard Maturity Score]]+tblRiskRegister32[[#This Row],[VCDB Index]],tblHITIndexWeightTable[],4,FALSE),"") | AB25: =VLOOKUP(tblRiskRegister32[[#This Row],[Asset Class]],tblInherentImpacts30[],2,FALSE) -> 0 | AC25: =VLOOKUP(tblRiskRegister32[[#This Row],[Asset Class]],tblInherentImpacts30[],3,FALSE) -> 0 | AD25: =VLOOKUP(tblRiskRegister32[[#This Row],[Asset Class]],tblInherentImpacts30[],4,FALSE) -> 0 | AE25: =VLOOKUP(tblRiskRegister32[[#This Row],[Asset Class]],tblInherentImpacts30[],5,FALSE) -> 0 | AF25: =IFERROR(MAX(tblRiskRegister32[[#This Row],[Risk Treatment Safeguard Impact to Mission]:[Risk Treatment Safeguard Impact to Obligations]])*tblRiskRegister32[[#This Row],[Risk Treatment Safeguard Expectancy Score]],"") | AG25: =IF(tblRiskRegister32[[#This Row],[Risk Score]]>=AcceptableRisk,IF(tblRiskRegister32[[#This Row],[Risk Treatment Safeguard Risk Score]]<AcceptableRisk, IF(tblRiskRegister32[[#This Row],[Risk Treatment Safeguard Risk Score]]<tblRiskRegister32[[#This Row],[Risk Score]],"Yes","No"),"No"),"Yes") -> No
B26: Data | D26: 3.6 | E26: Encrypt Data on End-User Devices | F26: x | G26: x | H26: Protect | M26: =IFERROR(VLOOKUP(tblRiskRegister32[[#This Row],[Asset Class]],tblVCDBIndex[],4,FALSE),"") -> 2 | N26: =IFERROR(VLOOKUP(10*tblRiskRegister32[[#This Row],[Safeguard Maturity Score]]+tblRiskRegister32[[#This Row],[VCDB Index]],tblHITIndexWeightTable[],4,FALSE),"") | O26: =VLOOKUP(tblRiskRegister32[[#This Row],[Asset Class]],tblInherentImpacts30[],2,FALSE) -> 0 | P26: =VLOOKUP(tblRiskRegister32[[#This Row],[Asset Class]],tblInherentImpacts30[],3,FALSE) -> 0 | Q26: =VLOOKUP(tblRiskRegister32[[#This Row],[Asset Class]],tblInherentImpacts30[],4,FALSE) -> 0 | R26: =VLOOKUP(tblRiskRegister32[[#This Row],[Asset Class]],tblInherentImpacts30[],5,FALSE) -> 0 | S26: =IFERROR(MAX(tblRiskRegister32[[#This Row],[Impact to Mission]:[Impact to Obligations]])*tblRiskRegister32[[#This Row],[Expectancy Score]],"") | T26: =tblRiskRegister32[[#This Row],[Risk Score]] | V26: 3.6 | W26: Encrypt Data on End-User Devices | X26: Encrypt data on end-user devices containing sensitive data. Example implementations can include: Windows BitLocker®, Apple FileVault®, Linux® dm-crypt. | AA26: =IFERROR(VLOOKUP(10*tblRiskRegister32[[#This Row],[Risk Treatment Safeguard Maturity Score]]+tblRiskRegister32[[#This Row],[VCDB Index]],tblHITIndexWeightTable[],4,FALSE),"") | AB26: =VLOOKUP(tblRiskRegister32[[#This Row],[Asset Class]],tblInherentImpacts30[],2,FALSE) -> 0 | AC26: =VLOOKUP(tblRiskRegister32[[#This Row],[Asset Class]],tblInherentImpacts30[],3,FALSE) -> 0 | AD26: =VLOOKUP(tblRiskRegister32[[#This Row],[Asset Class]],tblInherentImpacts30[],4,FALSE) -> 0 | AE26: =VLOOKUP(tblRiskRegister32[[#This Row],[Asset Class]],tblInherentImpacts30[],5,FALSE) -> 0 | AF26: =IFERROR(MAX(tblRiskRegister32[[#This Row],[Risk Treatment Safeguard Impact to Mission]:[Risk Treatment Safeguard Impact to Obligations]])*tblRiskRegister32[[#This Row],[Risk Treatment Safeguard Expectancy Score]],"") | AG26: =IF(tblRiskRegister32[[#This Row],[Risk Score]]>=AcceptableRisk,IF(tblRiskRegister32[[#This Row],[Risk Treatment Safeguard Risk Score]]<AcceptableRisk, IF(tblRiskRegister32[[#This Row],[Risk Treatment Safeguard Risk Score]]<tblRiskRegister32[[#This Row],[Risk Score]],"Yes","No"),"No"),"Yes") -> No
B27: Data | D27: 3.7 | E27: Establish and Maintain a Data Classification Scheme | G27: x | H27: Identify | M27: =IFERROR(VLOOKUP(tblRiskRegister32[[#This Row],[Asset Class]],tblVCDBIndex[],4,FALSE),"") -> 2 | N27: =IFERROR(VLOOKUP(10*tblRiskRegister32[[#This Row],[Safeguard Maturity Score]]+tblRiskRegister32[[#This Row],[VCDB Index]],tblHITIndexWeightTable[],4,FALSE),"") | O27: =VLOOKUP(tblRiskRegister32[[#This Row],[Asset Class]],tblInherentImpacts30[],2,FALSE) -> 0 | P27: =VLOOKUP(tblRiskRegister32[[#This Row],[Asset Class]],tblInherentImpacts30[],3,FALSE) -> 0 | Q27: =VLOOKUP(tblRiskRegister32[[#This Row],[Asset Class]],tblInherentImpacts30[],4,FALSE) -> 0 | R27: =VLOOKUP(tblRiskRegister32[[#This Row],[Asset Class]],tblInherentImpacts30[],5,FALSE) -> 0 | S27: =IFERROR(MAX(tblRiskRegister32[[#This Row],[Impact to Mission]:[Impact to Obligations]])*tblRiskRegister32[[#This Row],[Expectancy Score]],"") | T27: =tblRiskRegister32[[#This Row],[Risk Score]] | V27: 3.7 | W27: Establish and Maintain a Data Classification Scheme | X27: Establish and maintain an overall data classification scheme for the enterprise. Enterprises may use labels, such as “Sensitive,” “Confidential,” and “Public,” and classify their data according to those labels. Review and update the classification scheme annually, or when significant enterprise changes occur that could impact this Safeguard. | AA27: =IFERROR(VLOOKUP(10*tblRiskRegister32[[#This Row],[Risk Treatment Safeguard Maturity Score]]+tblRiskRegister32[[#This Row],[VCDB Index]],tblHITIndexWeightTable[],4,FALSE),"") | AB27: =VLOOKUP(tblRiskRegister32[[#This Row],[Asset Class]],tblInherentImpacts30[],2,FALSE) -> 0 | AC27: =VLOOKUP(tblRiskRegister32[[#This Row],[Asset Class]],tblInherentImpacts30[],3,FALSE) -> 0 | AD27: =VLOOKUP(tblRiskRegister32[[#This Row],[Asset Class]],tblInherentImpacts30[],4,FALSE) -> 0 | AE27: =VLOOKUP(tblRiskRegister32[[#This Row],[Asset Class]],tblInherentImpacts30[],5,FALSE) -> 0 | AF27: =IFERROR(MAX(tblRiskRegister32[[#This Row],[Risk Treatment Safeguard Impact to Mission]:[Risk Treatment Safeguard Impact to Obligations]])*tblRiskRegister32[[#This Row],[Risk Treatment Safeguard Expectancy Score]],"") | AG27: =IF(tblRiskRegister32[[#This Row],[Risk Score]]>=AcceptableRisk,IF(tblRiskRegister32[[#This Row],[Risk Treatment Safeguard Risk Score]]<AcceptableRisk, IF(tblRiskRegister32[[#This Row],[Risk Treatment Safeguard Risk Score]]<tblRiskRegister32[[#This Row],[Risk Score]],"Yes","No"),"No"),"Yes") -> No
